<?xml version='1.0'?>

<robot name="my_robot_2" xmlns:xacro="http://www.ros.org/wiki/xacro">
  <xacro:include filename="$(find my_robot)/urdf/my_robot.gazebo" />
  <link name="robot_footprint"></link>

  <joint name="robot_footprint_joint" type="fixed">
    <origin xyz="0 0 0" rpy="0 0 0" />
    <parent link="robot_footprint"/>
    <child link="chassis" />
  </joint>

  <link name='chassis'>
    <pose>0 0 0.4 0 0 0</pose>

    <inertial>
      <mass value="15.0"/>
      <origin xyz="0.0 0 0" rpy=" 0 0 0"/>
      <inertia
          ixx="0.1" ixy="0" ixz="0"
          iyy="0.1" iyz="0"
          izz="0.1"
      />
    </inertial>

    <collision name='collision'>
      <origin xyz="0 0 0" rpy=" 0 0 0"/>
      <geometry>
        <box size=".2 .2 .1"/>
      </geometry>
    </collision>

    <visual name='chassis_visual'>
      <origin xyz="0 0 0" rpy=" 0 0 0"/>
      <geometry>
        <box size=".2 .2 .1"/>
      </geometry>
    </visual>


    <collision name='back_caster_collision'>
      <origin xyz="-0.0625 0 -0.05" rpy=" 0 0 0"/>
      <geometry>
        <sphere radius="0.035"/>
      </geometry>
      <surface>
        <friction>
          <ode>
            <mu>0.0</mu>
            <mu1>0.0</mu1>
          </ode>
        </friction>
      </surface>
    </collision>

    <visual name='back_caster_visual'>
      <origin xyz="-0.0625 0 -0.05" rpy=" 0 0 0"/>
      <geometry>
        <sphere radius="0.035"/>
      </geometry>
    </visual>

    <collision name='front_caster_collision'>
      <origin xyz="0.0625 0 -0.05" rpy=" 0 0 0"/>
      <geometry>
        <sphere radius="0.035"/>
      </geometry>
      <surface>
        <friction>
          <ode>
            <mu>0.0</mu>
            <mu1>0.0</mu1>
          </ode>
        </friction>
      </surface>
    </collision>

    <visual name='front_caster_visual'>
      <origin xyz="0.0625 0 -0.05" rpy=" 0 0 0"/>
      <geometry>
        <sphere radius="0.035"/>
      </geometry>
    </visual>

  </link>

  <link name='left_wheel'>
    <collision name='left_wheel_collision'>
      <origin xyz="0 0 0" rpy="0 1.5707 1.5707" />
      <geometry>
      <cylinder radius="0.0875" length="0.0375" />
      </geometry>
    </collision>
    <visual name='left_wheel_visual'>
      <origin xyz="0 0 0" rpy="0 1.5707 1.5707" />
      <geometry>
      <cylinder radius="0.0875" length="0.0375" />
      </geometry>
    </visual>
    <inertial name='left_wheel_inertial'>
      <mass value="5.0"/>
      <origin xyz="0 0 0" rpy="0 1.5707 1.5707" />
      <inertia
          ixx="0.1" ixy="0" ixz="0"
          iyy="0.1" iyz="0"
          izz="0.1"
      />
    </inertial>

  </link>
  <joint type="continuous" name="left_wheel_hinge">
    <origin xyz="0 0.1375 0" rpy="0 0 0"/>
    <child link="left_wheel"/>
    <parent link="chassis"/>
    <axis xyz="0 1 0" rpy="0 0 0"/>
    <limit effort="10000" velocity="1000"/>
    <dynamics damping="1.0" friction="1.0"/>
  </joint>

  <link name='right_wheel'>
    <collision name='right_wheel_collision'>
      <origin xyz="0 0 0" rpy="0 1.5707 1.5707" />
      <geometry>
      <cylinder radius="0.0875" length="0.0375" />
      </geometry>
    </collision>
    <visual name='right_wheel_visual'>
      <origin xyz="0 0 0" rpy="0 1.5707 1.5707" />
      <geometry>
      <cylinder radius="0.0875" length="0.0375" />
      </geometry>
    </visual>
    <inertial name='right_wheel_inertial'>
      <mass value="5.0"/>
      <origin xyz="0 0 0" rpy="0 1.5707 1.5707" />
      <inertia
          ixx="0.1" ixy="0" ixz="0"
          iyy="0.1" iyz="0"
          izz="0.1"
      />
    </inertial>

  </link>
  <joint type="continuous" name="right_wheel_hinge">
    <origin xyz="0 -0.1375 0" rpy="0 0 0"/>
    <child link="right_wheel"/>
    <parent link="chassis"/>
    <axis xyz="0 1 0" rpy="0 0 0"/>
    <limit effort="10000" velocity="1000"/>
    <dynamics damping="1.0" friction="1.0"/>
  </joint>

  <link name="camera_link">
    <visual name="camera_visual">
      <origin xyz="0 0 0" rpy="0 0 0"/>
      <geometry>
        <box size="0.05 0.05 0.05" />
      </geometry>
    </visual>
    <collision name="camera_collision">
      <origin xyz="0 0 0" rpy="0 0 0"/>
      <geometry>
        <box size="0.05 0.05 0.05" />
      </geometry>
    </collision>
    <inertial name="box_intertia" params="0.1 0.05 0.05 0.05">
      <mass value="0.1"/>
      <origin xyz="0 0 0" rpy="0 0 0"/>
      <inertia
          ixx="1e-6" ixy="0" ixz="0"
          iyy="1e-6" iyz="0"
          izz="1e-6"
      />
    </inertial>
  </link>
  <joint type="fixed" name="camera_joint">
    <origin xyz="0.125 0 0.05" rpy="0 0 0 " />
    <axis xyz="0 1 0" rpy="0 0 0" />
    <parent link="chassis" />
    <child link="camera_link" />
  </joint>

  <link name="hokuyo">
    <visual name="hokuyo_visual">
      <origin xyz="0 0 0" rpy="0 0 0"/>
      <geometry>
        <mesh filename="package://my_robot/meshes/hokuyo.dae"/>
      </geometry>
    </visual>
    <collision name="hokuyo_collision">
      <origin xyz="0 0 0" rpy="0 0 0"/>
      <geometry>
        <box size="0.1 0.1 0.1" />
      </geometry>
    </collision>
    <inertial name="hokuyo_inertial">
      <mass value="1e-5"/>
      <origin xyz="0 0 0" rpy="0 0 0"/>
      <inertia
          ixx="1e-6" ixy="0" ixz="0"
          iyy="1e-6" iyz="0"
          izz="1e-6"
      />
    </inertial>

  </link>
  <joint type="fixed" name="hokuyo_joint">
    <origin xyz="0.0375 0 0.1" rpy="0 0 0" />
    <axis xyz="0 1 0" rpy="0 0 0" />
    <parent link="chassis" />
    <child link="hokuyo" />
  </joint>
  <joint name="camera_optical_joint" type="fixed">
    <origin xyz="0 0 0" rpy="-1.5707 0 -1.5707"/>
    <parent link="camera_link"/>
    <child link="camera_link_optical"/>
  </joint>

  <link name="camera_link_optical">
  </link>

</robot>
